<?xml version="1.0" encoding="UTF-8"?>
<!-- Generated by org.testng.reporters.JUnitReportReporter -->
<testsuite skipped="0" hostname="EONPC-18" name="com.lambdatest.SignUpTest" tests="14" failures="2" timestamp="2019-10-09T13:10:09 IST" time="182.367" errors="0">
  <testcase name="emptyNameTest" time="14.442" classname="com.lambdatest.SignUpTest"/>
  <testcase name="validRegistrationTest" time="20.513" classname="com.lambdatest.SignUpTest">
    <failure type="java.lang.AssertionError" message="expected [https://accounts.lambdatest.com/email/verify] but found [https://accounts.lambdatest.com/register]">
      <![CDATA[java.lang.AssertionError: expected [https://accounts.lambdatest.com/email/verify] but found [https://accounts.lambdatest.com/register]
at org.testng.Assert.fail(Assert.java:97)
at org.testng.Assert.assertEqualsImpl(Assert.java:136)
at org.testng.Assert.assertEquals(Assert.java:118)
at org.testng.Assert.assertEquals(Assert.java:575)
at org.testng.Assert.assertEquals(Assert.java:585)
at com.lambdatest.SignUpTest.validRegistrationTest(SignUpTest.java:192)
at sun.reflect.NativeMethodAccessorImpl.invoke0(Native Method)
at sun.reflect.NativeMethodAccessorImpl.invoke(Unknown Source)
at sun.reflect.DelegatingMethodAccessorImpl.invoke(Unknown Source)
at java.lang.reflect.Method.invoke(Unknown Source)
at org.testng.internal.MethodInvocationHelper.invokeMethod(MethodInvocationHelper.java:133)
at org.testng.internal.TestInvoker.invokeMethod(TestInvoker.java:584)
at org.testng.internal.TestInvoker.invokeTestMethod(TestInvoker.java:172)
at org.testng.internal.MethodRunner.runInSequence(MethodRunner.java:46)
at org.testng.internal.TestInvoker$MethodInvocationAgent.invoke(TestInvoker.java:804)
at org.testng.internal.TestInvoker.invokeTestMethods(TestInvoker.java:145)
at org.testng.internal.TestMethodWorker.invokeTestMethods(TestMethodWorker.java:146)
at org.testng.internal.TestMethodWorker.run(TestMethodWorker.java:128)
at java.util.ArrayList.forEach(Unknown Source)
at org.testng.TestRunner.privateRun(TestRunner.java:770)
at org.testng.TestRunner.run(TestRunner.java:591)
at org.testng.SuiteRunner.runTest(SuiteRunner.java:402)
at org.testng.SuiteRunner.access$000(SuiteRunner.java:41)
at org.testng.SuiteRunner$SuiteWorker.run(SuiteRunner.java:443)
at org.testng.internal.thread.ThreadUtil.lambda$execute$0(ThreadUtil.java:67)
at java.util.concurrent.FutureTask.run(Unknown Source)
at java.util.concurrent.ThreadPoolExecutor.runWorker(Unknown Source)
at java.util.concurrent.ThreadPoolExecutor$Worker.run(Unknown Source)
at java.lang.Thread.run(Unknown Source)
]]>
    </failure>
  </testcase> <!-- validRegistrationTest -->
  <testcase name="emptyPasswordTest" time="14.301" classname="com.lambdatest.SignUpTest"/>
  <testcase name="privacyPolicyRedirectionTest" time="8.497" classname="com.lambdatest.SignUpTest"/>
  <testcase name="inValidPhoneTest" time="14.173" classname="com.lambdatest.SignUpTest"/>
  <testcase name="inValidPasswordTest" time="13.881" classname="com.lambdatest.SignUpTest"/>
  <testcase name="emptyPhoneTest" time="14.709" classname="com.lambdatest.SignUpTest"/>
  <testcase name="emptyCompanyNameTest" time="14.961" classname="com.lambdatest.SignUpTest">
    <failure type="java.lang.AssertionError" message="expected [https://accounts.lambdatest.com/email/verify] but found [https://accounts.lambdatest.com/register]">
      <![CDATA[java.lang.AssertionError: expected [https://accounts.lambdatest.com/email/verify] but found [https://accounts.lambdatest.com/register]
at org.testng.Assert.fail(Assert.java:97)
at org.testng.Assert.assertEqualsImpl(Assert.java:136)
at org.testng.Assert.assertEquals(Assert.java:118)
at org.testng.Assert.assertEquals(Assert.java:575)
at org.testng.Assert.assertEquals(Assert.java:585)
at com.lambdatest.SignUpTest.emptyCompanyNameTest(SignUpTest.java:235)
at sun.reflect.NativeMethodAccessorImpl.invoke0(Native Method)
at sun.reflect.NativeMethodAccessorImpl.invoke(Unknown Source)
at sun.reflect.DelegatingMethodAccessorImpl.invoke(Unknown Source)
at java.lang.reflect.Method.invoke(Unknown Source)
at org.testng.internal.MethodInvocationHelper.invokeMethod(MethodInvocationHelper.java:133)
at org.testng.internal.TestInvoker.invokeMethod(TestInvoker.java:584)
at org.testng.internal.TestInvoker.invokeTestMethod(TestInvoker.java:172)
at org.testng.internal.MethodRunner.runInSequence(MethodRunner.java:46)
at org.testng.internal.TestInvoker$MethodInvocationAgent.invoke(TestInvoker.java:804)
at org.testng.internal.TestInvoker.invokeTestMethods(TestInvoker.java:145)
at org.testng.internal.TestMethodWorker.invokeTestMethods(TestMethodWorker.java:146)
at org.testng.internal.TestMethodWorker.run(TestMethodWorker.java:128)
at java.util.ArrayList.forEach(Unknown Source)
at org.testng.TestRunner.privateRun(TestRunner.java:770)
at org.testng.TestRunner.run(TestRunner.java:591)
at org.testng.SuiteRunner.runTest(SuiteRunner.java:402)
at org.testng.SuiteRunner.access$000(SuiteRunner.java:41)
at org.testng.SuiteRunner$SuiteWorker.run(SuiteRunner.java:443)
at org.testng.internal.thread.ThreadUtil.lambda$execute$0(ThreadUtil.java:67)
at java.util.concurrent.FutureTask.run(Unknown Source)
at java.util.concurrent.ThreadPoolExecutor.runWorker(Unknown Source)
at java.util.concurrent.ThreadPoolExecutor$Worker.run(Unknown Source)
at java.lang.Thread.run(Unknown Source)
]]>
    </failure>
  </testcase> <!-- emptyCompanyNameTest -->
  <testcase name="emptyEmailTest" time="14.269" classname="com.lambdatest.SignUpTest"/>
  <testcase name="invalidEmailTest" time="14.043" classname="com.lambdatest.SignUpTest"/>
  <testcase name="termsRedirectionTest" time="9.064" classname="com.lambdatest.SignUpTest"/>
  <testcase name="uncheckedTerms" time="13.011" classname="com.lambdatest.SignUpTest"/>
  <testcase name="loginRedirectionTest" time="7.399" classname="com.lambdatest.SignUpTest"/>
  <testcase name="verifyElemntsOnPageTest" time="9.104" classname="com.lambdatest.SignUpTest"/>
</testsuite> <!-- com.lambdatest.SignUpTest -->
